Workbook

Sheet 使い方
A1: このレポートの読み方(6ステップ)
A2: スコアを見る → 原因を特定する → 対応案を選ぶ → 実行して効果を追う、という流れで使います。
A4: STEP1 | B4: 総合スコアを見る
B5: 見る場所 | C5: 「シフト健全度」シート C3セル(総合健全度スコア)
B6: 判断基準 | C6: 80以上=安全 / 60〜79=要注意 / 60未満=要対応(バックアップ確保が必要)
B7: このデモでは | C7: 71.6 → 要注意(イベント重複時は厳しい可能性)
A9: STEP2 | B9: 弱い指標を特定する
B10: 見る場所 | C10: 「シフト健全度」シートの指標テーブル(教育達成率・属人化耐性・資格充足率・バックアップ率・変更耐性)
B11: あるあるパターン
B12: 指標 | C12: 低いとき、現場ではこう見えている | D12: 数値の目安
B13: 教育達成率が低い | C13: 「新人にはまだ早い」でリーダーが仕事を抱え込み、教育の時間が取れていない | D13: 70%以上: 順調 / 40〜70%: 要改善(教育投資を増やす) / 40%未満: 緊急(頭打ちの可能性大)
B14: 属人化耐性が低い | C14: 「あの人じゃないと分からない」設備がある。その人が休むと現場が止まる | D14: 80以上: 安全(3人以上対応可) / 40〜80: 要注意(1〜2人のみ) / 40未満: 危険(対応者ほぼ不在)
B15: 資格充足率が低い | C15: 実務はこなせているが、必要な資格を持たないまま対応している人がいる(安全・法令上のリスク) | D15: 80%以上: 良好 / 50〜80%: 要改善 / 50%未満: リスク大(無資格対応が多い)
B16: バックアップ率が低い | C16: 誰か1人が抜けると、代わりを探すのに毎回一苦労する | D16: 70%以上: 良好 / 40〜70%: 要改善 / 40%未満: リスク大(誰も代われない)
B17: 変更耐性が低い | C17: 急な欠勤・退職が出ると、その日のシフトが即座に組めなくなる | D17: 80以上: 安全 / 40〜80: 要注意 / 40未満: 危険(1人抜けたら即機能不全)
B18: このデモでは | C18: 教育達成率41.3・資格充足率50.0が低い → 上記の1番目・3番目のパターンに近い
A20: STEP3 | B20: 原因の場所を特定する
B21: 教育達成率が低い場合 | C21: 「頭打ち箇所と対応案」シートで、どのチーム・設備に教育担当が不在かを確認する
B22: 資格充足率が低い場合 | C22: 「シフト健全度」シートの資格充足率内訳で、どの設備の資格保有者が少ないかを確認する
B23: このデモでは | C23: チームD・Eに教育担当が1人もいない。電気工事士・冷凍機械責任者の保有者が少ない
A25: STEP4 | B25: 対応案を選ぶ
B26: 見る場所 | C26: 「頭打ち箇所と対応案」シートの4案(内部昇格/他チーム応援/常駐化+ローテーション制/チーム編成の見直し)
B27: 選び方の目安 | C27: 即効性重視なら他チームからの応援、恒久的な解決を目指すなら内部昇格やチーム編成の見直し
A29: STEP5 | B29: 個別の希望休を判断する
B30: 見る場所 | C30: 「希望休申請一覧」シートの判定列(G列)・必要人数列(K列)・交代要員の提案列(L列)
B31: 判断の目安 | C31: 早番Aは交代不要。早番B・夜勤で交代要員が提案されていれば、その人に打診したうえで承認する
B32: どうしても休む場合 | C32: 交代要員の「候補提案」まではシステムが自動で行うが、実際にシフト表へ反映し本人へ連絡するのは管理者の役割。L列に候補が出ない場合はSTEP4の対応案も検討する
A34: STEP6 | B34: 実行して効果を追跡する
B35: 実行 | C35: 選んだ対応策を来月のシフトに反映する
B36: 効果の確認 | C36: python src/future_simulation.py を実行すると、3・6・12ヶ月後の健全度予測が再計算できる
A38: STEP0 | B38: 【メンバー向け】スマホで健全度を見てから希望休を申請する
B39: 使うもの | C39: dashboard/ShiftDashboard.jsx(スマホのブラウザ/claude.aiのアーティファクトとして動作)
B40: 手順1 | C40: ダッシュボードを開き、メンバービューで自分の名前を選ぶ
B41: 手順2 | C41: 画面上部に表示される『現在の健全度』を見る(このデモではメンバー全員が同じ数値を見る組織全体の健全度)
B42: 手順3 | C42: 自分のシフトを確認し、休みたい日付・理由を入力して申請する
B43: 手順4 | C43: 申請は管理者ビューに即時反映され、承認/却下の結果もこの画面に表示される
B44: 現状の制約 | C44: 『この日にこの人が休んだら健全度が何点になるか』という個人単位のシミュレーションは、現バージョンでは管理者ビュー側(STEP4・5)でのみ確認できる。メンバー個人向けのシミュレーションはV2で検討

Sheet シフト健全度
A1: シフト健全度レポート(2026年8月時点)
A3: 総合健全度スコア | C3: =B13 -> 71.583333
A4: 判定 | C4: =IF(C3>=80,"安全:突発休暇があっても対応可能",IF(C3>=60,"要注意:イベント重複時は厳しい可能性","要対応:バックアップ確保が必要")) -> 要注意:イベント重複時は厳しい可能性
A6: 指標 | B6: スコア
A7: 教育達成率 | B7: =B39 -> 41.25
A8: 属人化耐性 | B8: =C21 -> 100
A9: 資格充足率 | B9: =D37 -> 50
A10: バックアップ率 | B10: =B40 -> 66.666667
A11: 変更耐性 | B11: =D30 -> 100
A13: 総合健全度スコア | B13: =AVERAGE(B7,B8,B9,B10,B11) -> 71.583333
A15: 属人化耐性 内訳(設備別: 単独対応以上の人数)
A16: 設備 | B16: 人数 | C16: スコア
A17: 受変電設備 | B17: =COUNTIF(メンバーデータ!K2:K16,">=2") -> 7 | C17: =MIN(B17,3)/3*100 -> 100
A18: 空調設備 | B18: =COUNTIF(メンバーデータ!L2:L16,">=2") -> 9 | C18: =MIN(B18,3)/3*100 -> 100
A19: 消防設備 | B19: =COUNTIF(メンバーデータ!M2:M16,">=2") -> 8 | C19: =MIN(B19,3)/3*100 -> 100
A20: 監視盤 | B20: =COUNTIF(メンバーデータ!N2:N16,">=2") -> 9 | C20: =MIN(B20,3)/3*100 -> 100
A21: 属人化耐性(総合) | C21: =AVERAGE(C17,C18,C19,C20) -> 100
A23: 変更耐性 内訳(チーム別: 単独対応可能人数)
A24: チーム | B24: 単独対応可能人数 | C24: チーム人数 | D24: スコア
A25: A | B25: =SUMIFS(メンバーデータ!$O:$O,メンバーデータ!$B:$B,"A") -> 3 | C25: =COUNTIF(メンバーデータ!$B:$B,"A") -> 3 | D25: =MIN(B25,2)/2*100 -> 100
A26: B | B26: =SUMIFS(メンバーデータ!$O:$O,メンバーデータ!$B:$B,"B") -> 2 | C26: =COUNTIF(メンバーデータ!$B:$B,"B") -> 3 | D26: =MIN(B26,2)/2*100 -> 100
A27: C | B27: =SUMIFS(メンバーデータ!$O:$O,メンバーデータ!$B:$B,"C") -> 2 | C27: =COUNTIF(メンバーデータ!$B:$B,"C") -> 3 | D27: =MIN(B27,2)/2*100 -> 100
A28: D | B28: =SUMIFS(メンバーデータ!$O:$O,メンバーデータ!$B:$B,"D") -> 2 | C28: =COUNTIF(メンバーデータ!$B:$B,"D") -> 3 | D28: =MIN(B28,2)/2*100 -> 100
A29: E | B29: =SUMIFS(メンバーデータ!$O:$O,メンバーデータ!$B:$B,"E") -> 2 | C29: =COUNTIF(メンバーデータ!$B:$B,"E") -> 3 | D29: =MIN(B29,2)/2*100 -> 100
A30: 変更耐性(総合) | D30: =AVERAGE(D25,D26,D27,D28,D29) -> 100
A32: 資格充足率 内訳(単独対応以上かつ必要資格を保有)
A33: 設備 | B33: 対象人数 | C33: 資格保有人数
A34: 受変電設備 | B34: =COUNTIF(メンバーデータ!K2:K16,">=2") -> 7 | C34: =SUMPRODUCT((メンバーデータ!K$2:K$16>=2)*((ISNUMBER(SEARCH("第二種電気工事士",メンバーデータ!$E$2:$E$16)))>0)) -> 3
A35: 空調設備 | B35: =COUNTIF(メンバーデータ!L2:L16,">=2") -> 9 | C35: =SUMPRODUCT((メンバーデータ!L$2:L$16>=2)*((ISNUMBER(SEARCH("第一種冷凍機械責任者",メンバーデータ!$E$2:$E$16))+ISNUMBER(SEARCH("第三種冷凍機械責任者",メンバーデータ!$E$2:$E$16)))>0)) -> 2
A36: 消防設備 | B36: =COUNTIF(メンバーデータ!M2:M16,">=2") -> 8 | C36: =SUMPRODUCT((メンバーデータ!M$2:M$16>=2)*((ISNUMBER(SEARCH("危険物取扱者乙4",メンバーデータ!$E$2:$E$16)))>0)) -> 7
A37: 資格充足率(総合) | B37: =SUM(B34,B35,B36) -> 24 | C37: =SUM(C34,C35,C36) -> 12 | D37: =C37/B37*100 -> 50
A39: 教育達成率 | B39: =AVERAGE(メンバーデータ!K2:N16)/4*100 -> 41.25
A40: バックアップ率 | B40: =COUNTIF(メンバーデータ!J2:J16,"?*")/COUNTA(メンバーデータ!A2:A16)*100 -> 66.666667
A42: 今月の早番A(教育投資枠)活用回数(チーム別)
A43: チーム | B43: 早A回数(今月)
A44: A | B44: =AVERAGEIF('シフト表(2026年8月)'!$B$2:$B$16,"A",'シフト表(2026年8月)'!$AI$2:$AI$16) -> 7
A45: B | B45: =AVERAGEIF('シフト表(2026年8月)'!$B$2:$B$16,"B",'シフト表(2026年8月)'!$AI$2:$AI$16) -> 6
A46: C | B46: =AVERAGEIF('シフト表(2026年8月)'!$B$2:$B$16,"C",'シフト表(2026年8月)'!$AI$2:$AI$16) -> 6
A47: D | B47: =AVERAGEIF('シフト表(2026年8月)'!$B$2:$B$16,"D",'シフト表(2026年8月)'!$AI$2:$AI$16) -> 6
A48: E | B48: =AVERAGEIF('シフト表(2026年8月)'!$B$2:$B$16,"E",'シフト表(2026年8月)'!$AI$2:$AI$16) -> 6
...

Sheet シフト表(2026年8月)
A1: 氏名 | B1: チーム | C1: 役職 | D1: 46235 | E1: 46236 | F1: 46237 | G1: 46238 | H1: 46239 | I1: 46240 | J1: 46241 | K1: 46242 | L1: 46243 | M1: 46244 | N1: 46245 | O1: 46246 | P1: 46247 | Q1: 46248 | R1: 46249 | S1: 46250 | T1: 46251 | U1: 46252 | V1: 46253 | W1: 46254 | X1: 46255 | Y1: 46256 | Z1: 46257 | AA1: 46258 | AB1: 46259 | AC1: 46260 | AD1: 46261 | AE1: 46262 | AF1: 46263 | AG1: 46264 | AH1: 46265 | AI1: 早A回数(今月)
A2: 佐藤 一郎 | B2: A | C2: リーダー | D2: 早A | E2: 早B | F2: 夜 | G2: 明 | H2: 休 | I2: 早A | J2: 早B | K2: 夜 | L2: 明 | M2: 休 | N2: 早A | O2: 早B | P2: 夜 | Q2: 明 | R2: 休 | S2: 早A | T2: 早B | U2: 夜 | V2: 明 | W2: 休 | X2: 早A | Y2: 早B | Z2: 夜 | AA2: 明 | AB2: 休 | AC2: 早A | AD2: 早B | AE2: 夜 | AF2: 明 | AG2: 休 | AH2: 早A | AI2: =COUNTIF(D2:AH2,"早A") -> 7
A3: 鈴木 次郎 | B3: B | C3: リーダー | D3: 早B | E3: 夜 | F3: 明 | G3: 休 | H3: 早A | I3: 早B | J3: 夜 | K3: 明 | L3: 休 | M3: 早A | N3: 早B | O3: 夜 | P3: 明 | Q3: 休 | R3: 早A | S3: 早B | T3: 夜 | U3: 明 | V3: 休 | W3: 早A | X3: 早B | Y3: 夜 | Z3: 明 | AA3: 休 | AB3: 早A | AC3: 早B | AD3: 夜 | AE3: 明 | AF3: 休 | AG3: 早A | AH3: 早B | AI3: =COUNTIF(D3:AH3,"早A") -> 6
A4: 高橋 三郎 | B4: C | C4: リーダー | D4: 夜 | E4: 明 | F4: 休 | G4: 早A | H4: 早B | I4: 夜 | J4: 明 | K4: 休 | L4: 早A | M4: 早B | N4: 夜 | O4: 明 | P4: 休 | Q4: 早A | R4: 早B | S4: 夜 | T4: 明 | U4: 休 | V4: 早A | W4: 早B | X4: 夜 | Y4: 明 | Z4: 休 | AA4: 早A | AB4: 早B | AC4: 夜 | AD4: 明 | AE4: 休 | AF4: 早A | AG4: 早B | AH4: 夜 | AI4: =COUNTIF(D4:AH4,"早A") -> 6
A5: 田中 誠 | B5: A | C5: 中堅 | D5: 早A | E5: 早B | F5: 夜 | G5: 明 | H5: 休 | I5: 早A | J5: 早B | K5: 夜 | L5: 明 | M5: 休 | N5: 早A | O5: 早B | P5: 夜 | Q5: 明 | R5: 休 | S5: 早A | T5: 早B | U5: 夜 | V5: 明 | W5: 休 | X5: 早A | Y5: 早B | Z5: 夜 | AA5: 明 | AB5: 休 | AC5: 早A | AD5: 早B | AE5: 夜 | AF5: 明 | AG5: 休 | AH5: 早A | AI5: =COUNTIF(D5:AH5,"早A") -> 7
A6: 伊藤 健太 | B6: B | C6: 中堅 | D6: 早B | E6: 夜 | F6: 明 | G6: 休 | H6: 早A | I6: 早B | J6: 夜 | K6: 明 | L6: 休 | M6: 早A | N6: 早B | O6: 夜 | P6: 明 | Q6: 休 | R6: 早A | S6: 早B | T6: 夜 | U6: 明 | V6: 休 | W6: 早A | X6: 早B | Y6: 夜 | Z6: 明 | AA6: 休 | AB6: 早A | AC6: 早B | AD6: 夜 | AE6: 明 | AF6: 休 | AG6: 早A | AH6: 早B | AI6: =COUNTIF(D6:AH6,"早A") -> 6
A7: 渡辺 修 | B7: C | C7: 中堅 | D7: 夜 | E7: 明 | F7: 休 | G7: 早A | H7: 早B | I7: 夜 | J7: 明 | K7: 休 | L7: 早A | M7: 早B | N7: 夜 | O7: 明 | P7: 休 | Q7: 早A | R7: 早B | S7: 夜 | T7: 明 | U7: 休 | V7: 早A | W7: 早B | X7: 夜 | Y7: 明 | Z7: 休 | AA7: 早A | AB7: 早B | AC7: 夜 | AD7: 明 | AE7: 休 | AF7: 早A | AG7: 早B | AH7: 夜 | AI7: =COUNTIF(D7:AH7,"早A") -> 6
A8: 山本 隆 | B8: D | C8: 中堅 | D8: 明 | E8: 休 | F8: 早A | G8: 早B | H8: 夜 | I8: 明 | J8: 休 | K8: 早A | L8: 早B | M8: 夜 | N8: 明 | O8: 休 | P8: 早A | Q8: 早B | R8: 夜 | S8: 明 | T8: 休 | U8: 早A | V8: 早B | W8: 夜 | X8: 明 | Y8: 休 | Z8: 早A | AA8: 早B | AB8: 夜 | AC8: 明 | AD8: 休 | AE8: 早A | AF8: 早B | AG8: 夜 | AH8: 明 | AI8: =COUNTIF(D8:AH8,"早A") -> 6
A9: 中村 陽介 | B9: A | C9: 一般 | D9: 早A | E9: 早B | F9: 夜 | G9: 明 | H9: 休 | I9: 早A | J9: 早B | K9: 夜 | L9: 明 | M9: 休 | N9: 早A | O9: 早B | P9: 夜 | Q9: 明 | R9: 休 | S9: 早A | T9: 早B | U9: 夜 | V9: 明 | W9: 休 | X9: 早A | Y9: 早B | Z9: 夜 | AA9: 明 | AB9: 休 | AC9: 早A | AD9: 早B | AE9: 夜 | AF9: 明 | AG9: 休 | AH9: 早A | AI9: =COUNTIF(D9:AH9,"早A") -> 7
A10: 小林 拓也 | B10: C | C10: 一般 | D10: 夜 | E10: 明 | F10: 休 | G10: 早A | H10: 早B | I10: 夜 | J10: 明 | K10: 休 | L10: 早A | M10: 早B | N10: 夜 | O10: 明 | P10: 休 | Q10: 早A | R10: 早B | S10: 夜 | T10: 明 | U10: 休 | V10: 早A | W10: 早B | X10: 夜 | Y10: 明 | Z10: 休 | AA10: 早A | AB10: 早B | AC10: 夜 | AD10: 明 | AE10: 休 | AF10: 早A | AG10: 早B | AH10: 夜 | AI10: =COUNTIF(D10:AH10,"早A") -> 6
A11: 加藤 大輔 | B11: D | C11: サブリーダー | D11: 明 | E11: 休 | F11: 早A | G11: 早B | H11: 夜 | I11: 明 | J11: 休 | K11: 早A | L11: 早B | M11: 夜 | N11: 明 | O11: 休 | P11: 早A | Q11: 早B | R11: 夜 | S11: 明 | T11: 休 | U11: 早A | V11: 早B | W11: 夜 | X11: 明 | Y11: 休 | Z11: 早A | AA11: 早B | AB11: 夜 | AC11: 明 | AD11: 休 | AE11: 早A | AF11: 早B | AG11: 夜 | AH11: 明 | AI11: =COUNTIF(D11:AH11,"早A") -> 6
A12: 吉田 匠 | B12: E | C12: サブリーダー | D12: 休 | E12: 早A | F12: 早B | G12: 夜 | H12: 明 | I12: 休 | J12: 早A | K12: 早B | L12: 夜 | M12: 明 | N12: 休 | O12: 早A | P12: 早B | Q12: 夜 | R12: 明 | S12: 休 | T12: 早A | U12: 早B | V12: 夜 | W12: 明 | X12: 休 | Y12: 早A | Z12: 早B | AA12: 夜 | AB12: 明 | AC12: 休 | AD12: 早A | AE12: 早B | AF12: 夜 | AG12: 明 | AH12: 休 | AI12: =COUNTIF(D12:AH12,"早A") -> 6
A13: 山田 悠斗 | B13: B | C13: 新人 | D13: 早B | E13: 夜 | F13: 明 | G13: 休 | H13: 早A | I13: 早B | J13: 夜 | K13: 明 | L13: 休 | M13: 早A | N13: 早B | O13: 夜 | P13: 明 | Q13: 休 | R13: 早A | S13: 早B | T13: 夜 | U13: 明 | V13: 休 | W13: 早A | X13: 早B | Y13: 夜 | Z13: 明 | AA13: 休 | AB13: 早A | AC13: 早B | AD13: 夜 | AE13: 明 | AF13: 休 | AG13: 早A | AH13: 早B | AI13: =COUNTIF(D13:AH13,"早A") -> 6
... A16: 井上 直樹 | B16: E | C16: 一般 | D16: 休 | E16: 早A | F16: 早B | G16: 夜 | H16: 明 | I16: 休 | J16: 早A | K16: 早B | L16: 夜 | M16: 明 | N16: 休 | O16: 早A | P16: 早B | Q16: 夜 | R16: 明 | S16: 休 | T16: 早A | U16: 早B | V16: 夜 | W16: 明 | X16: 休 | Y16: 早A | Z16: 早B | AA16: 夜 | AB16: 明 | AC16: 休 | AD16: 早A | AE16: 早B | AF16: 夜 | AG16: 明 | AH16: 休 | AI16: =COUNTIF(D16:AH16,"早A") -> 6
A18: 凡例:
A19: 早A | B19: 早番A(教育投資枠)
A20: 早B | B20: 早番B
A21: 夜 | B21: 夜勤
A22: 明 | B22: 明け
A23: 休 | B23: 休み
A24: 太赤枠 | B24: 希望休の申請あり

Sheet 希望休申請一覧
A1: 現在のシフト健全度: | B1: =シフト健全度!C3 -> 71.583333 | C1: =シフト健全度!C4 -> 要注意:イベント重複時は厳しい可能性
A3: 氏名 | B3: チーム | C3: 希望日 | D3: 理由 | E3: 割当中のシフト | F3: 承認後のチーム残(単独対応以上)人数 | G3: 判定 | H3: 申請日 | I3: 自動承認可否 | J3: 自動承認/手動確認の理由 | K3: 必要人数 | L3: 交代要員の提案
A4: 田中 誠 | B4: =VLOOKUP(A4,メンバーデータ!$A:$B,2,FALSE()) -> A | C4: 46244 | D4: (初期データ) | E4: =INDEX('シフト表(2026年8月)'!$D$2:$AH$16,MATCH($A4,'シフト表(2026年8月)'!$A$2:$A$16,0),MATCH($C4,'シフト表(2026年8月)'!$D$1:$AH$1,0)) -> 休 | F4: =SUMIFS(メンバーデータ!$O:$O,メンバーデータ!$B:$B,B4)-VLOOKUP(A4,メンバーデータ!$A:$O,15,FALSE()) -> 2 | G4: =IF(F4>=2,"バックアップ不要",IF(F4=1,"要注意(イベント時はバックアップ検討)","バックアップ出動が必要")) -> バックアップ不要 | H4: 46204 | I4: 自動承認 | J4: 申請期限・週40時間・必要人数・NGペアのいずれも問題なし → 自動承認 | K4: 0 | L4: 交代不要
A5: 田中 誠 | B5: =VLOOKUP(A5,メンバーデータ!$A:$B,2,FALSE()) -> A | C5: 46245 | D5: (初期データ) | E5: =INDEX('シフト表(2026年8月)'!$D$2:$AH$16,MATCH($A5,'シフト表(2026年8月)'!$A$2:$A$16,0),MATCH($C5,'シフト表(2026年8月)'!$D$1:$AH$1,0)) -> 早A | F5: =SUMIFS(メンバーデータ!$O:$O,メンバーデータ!$B:$B,B5)-VLOOKUP(A5,メンバーデータ!$A:$O,15,FALSE()) -> 2 | G5: =IF(F5>=2,"バックアップ不要",IF(F5=1,"要注意(イベント時はバックアップ検討)","バックアップ出動が必要")) -> バックアップ不要 | H5: 46204 | I5: 自動承認 | J5: 早番A(教育投資枠)の希望休のため、運行への影響なし → 自動承認 | K5: 0 | L5: 交代不要
A6: 山田 悠斗 | B6: =VLOOKUP(A6,メンバーデータ!$A:$B,2,FALSE()) -> B | C6: 46254 | D6: (初期データ) | E6: =INDEX('シフト表(2026年8月)'!$D$2:$AH$16,MATCH($A6,'シフト表(2026年8月)'!$A$2:$A$16,0),MATCH($C6,'シフト表(2026年8月)'!$D$1:$AH$1,0)) -> 早A | F6: =SUMIFS(メンバーデータ!$O:$O,メンバーデータ!$B:$B,B6)-VLOOKUP(A6,メンバーデータ!$A:$O,15,FALSE()) -> 2 | G6: =IF(F6>=2,"バックアップ不要",IF(F6=1,"要注意(イベント時はバックアップ検討)","バックアップ出動が必要")) -> バックアップ不要 | H6: 46223 | I6: 自動承認 | J6: 早番A(教育投資枠)の希望休のため、運行への影響なし → 自動承認 | K6: 0 | L6: 交代不要
A7: 小林 拓也 | B7: =VLOOKUP(A7,メンバーデータ!$A:$B,2,FALSE()) -> C | C7: 46249 | D7: (初期データ) | E7: =INDEX('シフト表(2026年8月)'!$D$2:$AH$16,MATCH($A7,'シフト表(2026年8月)'!$A$2:$A$16,0),MATCH($C7,'シフト表(2026年8月)'!$D$1:$AH$1,0)) -> 早B | F7: =SUMIFS(メンバーデータ!$O:$O,メンバーデータ!$B:$B,B7)-VLOOKUP(A7,メンバーデータ!$A:$O,15,FALSE()) -> 2 | G7: =IF(F7>=2,"バックアップ不要",IF(F7=1,"要注意(イベント時はバックアップ検討)","バックアップ出動が必要")) -> バックアップ不要 | H7: 46239 | I7: 手動確認 | J7: 申請期限(14日前まで)を満たしていない(実際: 10日前) / 週40時間の労働時間超過がチーム内に存在するため、健全度に関係なく手動確認が必要(高橋 三郎、渡辺 修、小林 拓也) / 中村 陽介とのNGペア調整が絡むため当事者間の確認が必要 | K7: 3 | L7: 小林 拓也 → 佐藤 一郎(チームA)
A8: 小林 拓也 | B8: =VLOOKUP(A8,メンバーデータ!$A:$B,2,FALSE()) -> C | C8: 46250 | D8: (初期データ) | E8: =INDEX('シフト表(2026年8月)'!$D$2:$AH$16,MATCH($A8,'シフト表(2026年8月)'!$A$2:$A$16,0),MATCH($C8,'シフト表(2026年8月)'!$D$1:$AH$1,0)) -> 夜 | F8: =SUMIFS(メンバーデータ!$O:$O,メンバーデータ!$B:$B,B8)-VLOOKUP(A8,メンバーデータ!$A:$O,15,FALSE()) -> 2 | G8: =IF(F8>=2,"バックアップ不要",IF(F8=1,"要注意(イベント時はバックアップ検討)","バックアップ出動が必要")) -> バックアップ不要 | H8: 46239 | I8: 手動確認 | J8: 申請期限(14日前まで)を満たしていない(実際: 11日前) / 週40時間の労働時間超過がチーム内に存在するため、健全度に関係なく手動確認が必要(高橋 三郎、渡辺 修、小林 拓也) / 中村 陽介とのNGペア調整が絡むため当事者間の確認が必要 | K8: 3 | L8: 小林 拓也 → 山本 隆(チームD)
A9: 小林 拓也 | B9: =VLOOKUP(A9,メンバーデータ!$A:$B,2,FALSE()) -> C | C9: 46251 | D9: (初期データ) | E9: =INDEX('シフト表(2026年8月)'!$D$2:$AH$16,MATCH($A9,'シフト表(2026年8月)'!$A$2:$A$16,0),MATCH($C9,'シフト表(2026年8月)'!$D$1:$AH$1,0)) -> 明 | F9: =SUMIFS(メンバーデータ!$O:$O,メンバーデータ!$B:$B,B9)-VLOOKUP(A9,メンバーデータ!$A:$O,15,FALSE()) -> 2 | G9: =IF(F9>=2,"バックアップ不要",IF(F9=1,"要注意(イベント時はバックアップ検討)","バックアップ出動が必要")) -> バックアップ不要 | H9: 46239 | I9: 手動確認 | J9: 申請期限(14日前まで)を満たしていない(実際: 12日前) / 中村 陽介とのNGペア調整が絡むため当事者間の確認が必要 | K9: 0 | L9: 交代不要
A11: ※「承認後のチーム残人数」は、そのチームで設備を単独対応以上でこなせる人数から、申請者本人の分を除いた人数です。
A12: ※「自動承認可否」はsrc/auto_approval.pyで計算した値です(申請期限・週40時間・残人数・NGペアをすべて満たす場合のみ自動承認)。設定は「労働時間・自動承認設定」シート参照。

Sheet 労働時間・自動承認設定
A1: 労働時間チェック・自動承認設定
A2: 週40時間を超える勤務は、シフト健全度の良し悪しとは無関係にチェックする(健全度が高くても法令上の問題は残るため)。
A4: 自動承認設定(管理者がON/OFFできる)
A5: 自動承認機能 | B5: 有効
A6: 申請期限(◯日前まで) | B6: 14日前まで
A7: 最低必要バックアップ人数 | B7: 2人
A9: 自動承認の条件(すべて満たした場合のみ、管理者の承認なしで通る)
A10: 1. 自動承認機能が有効になっている(上記設定)
A11: 2. 申請日から希望日まで、設定した日数以上ある(直前の申請は対象外)
A12: 3. その週にチーム内で週40時間超えが無い(法令順守を優先し、健全度に関係なくブロック)
A13: 4. 承認後もチームに単独対応できる人が十分残る(健全度への影響が小さい)
A14: 5. NGペアの相手が関わる、当事者間の調整が必要な状況ではない
A16: 週40時間の労働時間チェック結果(2026年8月・デモ)
A17: 氏名 | B17: チーム | C17: 週 | D17: 時間 | E17: 上限
A18: 佐藤 一郎 | B18: A | C18: 2026-W32 | D18: 48 | E18: 40
A19: 佐藤 一郎 | B19: A | C19: 2026-W34 | D19: 56 | E19: 40
A20: 鈴木 次郎 | B20: B | C20: 2026-W33 | D20: 48 | E20: 40
A21: 鈴木 次郎 | B21: B | C21: 2026-W34 | D21: 48 | E21: 40
A22: 高橋 三郎 | B22: C | C22: 2026-W33 | D22: 56 | E22: 40
A23: 高橋 三郎 | B23: C | C23: 2026-W35 | D23: 48 | E23: 40
A24: 田中 誠 | B24: A | C24: 2026-W32 | D24: 48 | E24: 40
A25: 田中 誠 | B25: A | C25: 2026-W34 | D25: 56 | E25: 40
A26: 伊藤 健太 | B26: B | C26: 2026-W33 | D26: 48 | E26: 40
A27: 伊藤 健太 | B27: B | C27: 2026-W34 | D27: 48 | E27: 40
A28: 渡辺 修 | B28: C | C28: 2026-W33 | D28: 56 | E28: 40
A29: 渡辺 修 | B29: C | C29: 2026-W35 | D29: 48 | E29: 40
... A53: 井上 直樹 | B53: E | C53: 2026-W35 | D53: 48 | E53: 40
A55: ※ このデモは「早番A/早番B=8時間、夜勤=16時間」という単純な前提で計算している。実際の24時間現場では、夜勤を含むシフトは「1ヶ月単位の変形労働時間制」等で運用され、週単位ではなく月単位で平均をとるのが一般的。本チェックはあくまで週単位の簡易チェックであり、実際の適法性判断には社会保険労務士等への確認を推奨する。
A59: 参考: 関連する法令メモ(簡易チェックの前提として)
A60: 項目 | B60: 内容
A61: 36協定(原則) | B61: 月45時間までの残業は毎月可能(年360時間以内)。
A62: 36協定(特別条項) | B62: 月45時間を「超える」残業ができるのが年6回まで。
A63: 1日8時間超のシフト | B63: 「変形労働時間制」を導入していれば、所定労働時間として8時間超の設定が可能。
A64: 日付またぎの勤務 | B64: 暦日に関わらず「1つの勤務」として計算される。休憩(8時間超で1時間以上)と割増賃金を支払えば16時間拘束も可能。
A66: ※ 上記は一般的な制度の概要であり、事業場ごとの労使協定・就業規則の内容が優先される。個別の適用可否は社会保険労務士等に確認すること。

Sheet 頭打ち箇所と対応案
A1: 教育担当が不在で頭打ちになっている箇所と対応案
A3: 頭打ち箇所(チーム×設備の組み合わせ数) | B3: 13
A4: 実際に昇格が必要な人数 | B4: 5 | C4: (1人が同じチーム内の複数設備を兼任できるため、組み合わせ数より少なくて済む)
A6: 候補者 | B6: 担当する(チーム/設備) | C6: 件数
A7: 佐藤 一郎 | B7: A/消防設備 | C7: 1
A8: 鈴木 次郎 | B8: B/空調設備, B/監視盤 | C8: 2
A9: 高橋 三郎 | B9: C/受変電設備, C/消防設備 | C9: 2
A10: 加藤 大輔 | B10: D/受変電設備, D/空調設備, D/消防設備, D/監視盤 | C10: 4
A11: 吉田 匠 | B11: E/受変電設備, E/空調設備, E/消防設備, E/監視盤 | C11: 4
A14: 箇所ごとの対応案(4案)
A15: チーム/設備 | B15: 案1: 内部昇格 | C15: 案2: 他チームからの応援 | D15: 案3: 常駐化+ローテーション制 | E15: 案4: チーム編成の見直し(異動)
A16: チームA / 消防設備 | B16: 佐藤 一郎(現在 単独)を教育担当に育てる | C16: 鈴木 次郎(チームB) を臨時にチームAの早番Aへ応援に回す | D16: 佐藤 一郎など最もスキルの高いメンバーを一時的に教育専任(常日勤)にする。ただし固定化すると不公平感が出るため、対象者を数ヶ月ごとに交代するローテーション制にする | E16: 鈴木 次郎(チームB)を チームA へ恒久的に異動する。異動元(チームB)には他に単独対応以上の人が残るため、教育体制は維持される
A17: チームB / 空調設備 | B17: 鈴木 次郎(現在 単独)を教育担当に育てる | C17: 佐藤 一郎(チームA)、高橋 三郎(チームC) を臨時にチームBの早番Aへ応援に回す | D17: 鈴木 次郎など最もスキルの高いメンバーを一時的に教育専任(常日勤)にする。ただし固定化すると不公平感が出るため、対象者を数ヶ月ごとに交代するローテーション制にする | E17: 佐藤 一郎(チームA)を チームB へ恒久的に異動する。異動元(チームA)には他に単独対応以上の人が残るため、教育体制は維持される
A18: チームB / 監視盤 | B18: 鈴木 次郎(現在 単独)を教育担当に育てる | C18: 佐藤 一郎(チームA)、高橋 三郎(チームC) を臨時にチームBの早番Aへ応援に回す | D18: 鈴木 次郎など最もスキルの高いメンバーを一時的に教育専任(常日勤)にする。ただし固定化すると不公平感が出るため、対象者を数ヶ月ごとに交代するローテーション制にする | E18: 佐藤 一郎(チームA)を チームB へ恒久的に異動する。異動元(チームA)には他に単独対応以上の人が残るため、教育体制は維持される
A19: チームC / 受変電設備 | B19: 高橋 三郎(現在 単独)を教育担当に育てる | C19: 佐藤 一郎(チームA)、鈴木 次郎(チームB) を臨時にチームCの早番Aへ応援に回す | D19: 高橋 三郎など最もスキルの高いメンバーを一時的に教育専任(常日勤)にする。ただし固定化すると不公平感が出るため、対象者を数ヶ月ごとに交代するローテーション制にする | E19: 佐藤 一郎(チームA)を チームC へ恒久的に異動する。異動元(チームA)には他に単独対応以上の人が残るため、教育体制は維持される
A20: チームC / 消防設備 | B20: 高橋 三郎(現在 単独)を教育担当に育てる | C20: 鈴木 次郎(チームB) を臨時にチームCの早番Aへ応援に回す | D20: 高橋 三郎など最もスキルの高いメンバーを一時的に教育専任(常日勤)にする。ただし固定化すると不公平感が出るため、対象者を数ヶ月ごとに交代するローテーション制にする | E20: 鈴木 次郎(チームB)を チームC へ恒久的に異動する。異動元(チームB)には他に単独対応以上の人が残るため、教育体制は維持される
A21: チームD / 受変電設備 | B21: 加藤 大輔(現在 単独)を教育担当に育てる | C21: 佐藤 一郎(チームA)、鈴木 次郎(チームB) を臨時にチームDの早番Aへ応援に回す | D21: 加藤 大輔など最もスキルの高いメンバーを一時的に教育専任(常日勤)にする。ただし固定化すると不公平感が出るため、対象者を数ヶ月ごとに交代するローテーション制にする | E21: 佐藤 一郎(チームA)を チームD へ恒久的に異動する。異動元(チームA)には他に単独対応以上の人が残るため、教育体制は維持される
A22: チームD / 空調設備 | B22: 加藤 大輔(現在 教育担当補助)を教育担当に育てる | C22: 佐藤 一郎(チームA)、高橋 三郎(チームC) を臨時にチームDの早番Aへ応援に回す | D22: 加藤 大輔など最もスキルの高いメンバーを一時的に教育専任(常日勤)にする。ただし固定化すると不公平感が出るため、対象者を数ヶ月ごとに交代するローテーション制にする | E22: 佐藤 一郎(チームA)を チームD へ恒久的に異動する。異動元(チームA)には他に単独対応以上の人が残るため、教育体制は維持される
A23: チームD / 消防設備 | B23: 加藤 大輔(現在 単独)を教育担当に育てる | C23: 鈴木 次郎(チームB) を臨時にチームDの早番Aへ応援に回す | D23: 加藤 大輔など最もスキルの高いメンバーを一時的に教育専任(常日勤)にする。ただし固定化すると不公平感が出るため、対象者を数ヶ月ごとに交代するローテーション制にする | E23: 鈴木 次郎(チームB)を チームD へ恒久的に異動する。異動元(チームB)には他に単独対応以上の人が残るため、教育体制は維持される
A24: チームD / 監視盤 | B24: 加藤 大輔(現在 教育担当補助)を教育担当に育てる | C24: 佐藤 一郎(チームA)、高橋 三郎(チームC) を臨時にチームDの早番Aへ応援に回す | D24: 加藤 大輔など最もスキルの高いメンバーを一時的に教育専任(常日勤)にする。ただし固定化すると不公平感が出るため、対象者を数ヶ月ごとに交代するローテーション制にする | E24: 佐藤 一郎(チームA)を チームD へ恒久的に異動する。異動元(チームA)には他に単独対応以上の人が残るため、教育体制は維持される
A25: チームE / 受変電設備 | B25: 吉田 匠(現在 単独)を教育担当に育てる | C25: 佐藤 一郎(チームA)、鈴木 次郎(チームB) を臨時にチームEの早番Aへ応援に回す | D25: 吉田 匠など最もスキルの高いメンバーを一時的に教育専任(常日勤)にする。ただし固定化すると不公平感が出るため、対象者を数ヶ月ごとに交代するローテーション制にする | E25: 佐藤 一郎(チームA)を チームE へ恒久的に異動する。異動元(チームA)には他に単独対応以上の人が残るため、教育体制は維持される
A26: チームE / 空調設備 | B26: 吉田 匠(現在 単独)を教育担当に育てる | C26: 佐藤 一郎(チームA)、高橋 三郎(チームC) を臨時にチームEの早番Aへ応援に回す | D26: 吉田 匠など最もスキルの高いメンバーを一時的に教育専任(常日勤)にする。ただし固定化すると不公平感が出るため、対象者を数ヶ月ごとに交代するローテーション制にする | E26: 佐藤 一郎(チームA)を チームE へ恒久的に異動する。異動元(チームA)には他に単独対応以上の人が残るため、教育体制は維持される
... A28: チームE / 監視盤 | B28: 吉田 匠(現在 単独)を教育担当に育てる | C28: 佐藤 一郎(チームA)、高橋 三郎(チームC) を臨時にチームEの早番Aへ応援に回す | D28: 吉田 匠など最もスキルの高いメンバーを一時的に教育専任(常日勤)にする。ただし固定化すると不公平感が出るため、対象者を数ヶ月ごとに交代するローテーション制にする | E28: 佐藤 一郎(チームA)を チームE へ恒久的に異動する。異動元(チームA)には他に単独対応以上の人が残るため、教育体制は維持される
A30: 「常駐化+ローテーション制」は、最もスキルの高いメンバーを一時的に教育専任(常日勤)にする案。ただし特定の1人に固定すると不公平感が出るため、対象者を数ヶ月ごとに交代する運用を想定している。

Sheet メンバーデータ
A1: 氏名 | B1: チーム | C1: 役職 | D1: 経験月数 | E1: 資格 | F1: 受変電設備段階 | G1: 空調設備段階 | H1: 消防設備段階 | I1: 監視盤段階 | J1: バックアップ可能業務 | K1: 受変電_数値 | L1: 空調_数値 | M1: 消防_数値 | N1: 監視盤_数値 | O1: いずれかで単独以上か
A2: 佐藤 一郎 | B2: A | C2: リーダー | D2: 118 | E2: 第二種電気工事士, 危険物取扱者乙4, 第一種冷凍機械責任者 | F2: 教育担当 | G2: 教育担当 | H2: 単独 | I2: 教育担当 | J2: 夜勤リーダー代行, 資格更新管理, 新人教育計画 | K2: =VLOOKUP(F2,段階マップ!$A:$B,2,FALSE()) -> 4 | L2: =VLOOKUP(G2,段階マップ!$A:$B,2,FALSE()) -> 4 | M2: =VLOOKUP(H2,段階マップ!$A:$B,2,FALSE()) -> 2 | N2: =VLOOKUP(I2,段階マップ!$A:$B,2,FALSE()) -> 4 | O2: =IF(MAX(K2:N2)>=2,1,0) -> 1
A3: 鈴木 次郎 | B3: B | C3: リーダー | D3: 104 | E3: 第二種電気工事士, 危険物取扱者乙4 | F3: 教育担当 | G3: 単独 | H3: 教育担当 | I3: 単独 | J3: 夜勤リーダー代行, イベント対応統括 | K3: =VLOOKUP(F3,段階マップ!$A:$B,2,FALSE()) -> 4 | L3: =VLOOKUP(G3,段階マップ!$A:$B,2,FALSE()) -> 2 | M3: =VLOOKUP(H3,段階マップ!$A:$B,2,FALSE()) -> 4 | N3: =VLOOKUP(I3,段階マップ!$A:$B,2,FALSE()) -> 2 | O3: =IF(MAX(K3:N3)>=2,1,0) -> 1
A4: 高橋 三郎 | B4: C | C4: リーダー | D4: 96 | E4: 危険物取扱者乙4, 第三種冷凍機械責任者 | F4: 単独 | G4: 教育担当 | H4: 単独 | I4: 教育担当 | J4: 夜勤リーダー代行, 教育担当補助の育成 | K4: =VLOOKUP(F4,段階マップ!$A:$B,2,FALSE()) -> 2 | L4: =VLOOKUP(G4,段階マップ!$A:$B,2,FALSE()) -> 4 | M4: =VLOOKUP(H4,段階マップ!$A:$B,2,FALSE()) -> 2 | N4: =VLOOKUP(I4,段階マップ!$A:$B,2,FALSE()) -> 4 | O4: =IF(MAX(K4:N4)>=2,1,0) -> 1
A5: 田中 誠 | B5: A | C5: 中堅 | D5: 46 | E5: 危険物取扱者乙4 | F5: 単独 | G5: 単独 | H5: 補助 | I5: 単独 | J5: 夜勤単独対応 | K5: =VLOOKUP(F5,段階マップ!$A:$B,2,FALSE()) -> 2 | L5: =VLOOKUP(G5,段階マップ!$A:$B,2,FALSE()) -> 2 | M5: =VLOOKUP(H5,段階マップ!$A:$B,2,FALSE()) -> 1 | N5: =VLOOKUP(I5,段階マップ!$A:$B,2,FALSE()) -> 2 | O5: =IF(MAX(K5:N5)>=2,1,0) -> 1
A6: 伊藤 健太 | B6: B | C6: 中堅 | D6: 41 | E6: 危険物取扱者乙4 | F6: 単独 | G6: 補助 | H6: 単独 | I6: 単独 | J6: 夜勤単独対応 | K6: =VLOOKUP(F6,段階マップ!$A:$B,2,FALSE()) -> 2 | L6: =VLOOKUP(G6,段階マップ!$A:$B,2,FALSE()) -> 1 | M6: =VLOOKUP(H6,段階マップ!$A:$B,2,FALSE()) -> 2 | N6: =VLOOKUP(I6,段階マップ!$A:$B,2,FALSE()) -> 2 | O6: =IF(MAX(K6:N6)>=2,1,0) -> 1
A7: 渡辺 修 | B7: C | C7: 中堅 | D7: 38 | F7: 補助 | G7: 単独 | H7: 単独 | I7: 補助 | J7: 空調設備対応 | K7: =VLOOKUP(F7,段階マップ!$A:$B,2,FALSE()) -> 1 | L7: =VLOOKUP(G7,段階マップ!$A:$B,2,FALSE()) -> 2 | M7: =VLOOKUP(H7,段階マップ!$A:$B,2,FALSE()) -> 2 | N7: =VLOOKUP(I7,段階マップ!$A:$B,2,FALSE()) -> 1 | O7: =IF(MAX(K7:N7)>=2,1,0) -> 1
A8: 山本 隆 | B8: D | C8: 中堅 | D8: 35 | E8: 危険物取扱者乙4 | F8: 補助 | G8: 単独 | H8: 補助 | I8: 単独 | J8: 監視盤対応 | K8: =VLOOKUP(F8,段階マップ!$A:$B,2,FALSE()) -> 1 | L8: =VLOOKUP(G8,段階マップ!$A:$B,2,FALSE()) -> 2 | M8: =VLOOKUP(H8,段階マップ!$A:$B,2,FALSE()) -> 1 | N8: =VLOOKUP(I8,段階マップ!$A:$B,2,FALSE()) -> 2 | O8: =IF(MAX(K8:N8)>=2,1,0) -> 1
A9: 中村 陽介 | B9: A | C9: 一般 | D9: 20 | F9: 補助 | G9: 補助 | H9: 見学 | I9: 単独 | K9: =VLOOKUP(F9,段階マップ!$A:$B,2,FALSE()) -> 1 | L9: =VLOOKUP(G9,段階マップ!$A:$B,2,FALSE()) -> 1 | M9: =VLOOKUP(H9,段階マップ!$A:$B,2,FALSE()) -> 0 | N9: =VLOOKUP(I9,段階マップ!$A:$B,2,FALSE()) -> 2 | O9: =IF(MAX(K9:N9)>=2,1,0) -> 1
A10: 小林 拓也 | B10: C | C10: 一般 | D10: 16 | F10: 見学 | G10: 補助 | H10: 補助 | I10: 補助 | K10: =VLOOKUP(F10,段階マップ!$A:$B,2,FALSE()) -> 0 | L10: =VLOOKUP(G10,段階マップ!$A:$B,2,FALSE()) -> 1 | M10: =VLOOKUP(H10,段階マップ!$A:$B,2,FALSE()) -> 1 | N10: =VLOOKUP(I10,段階マップ!$A:$B,2,FALSE()) -> 1 | O10: =IF(MAX(K10:N10)>=2,1,0) -> 0
A11: 加藤 大輔 | B11: D | C11: サブリーダー | D11: 68 | E11: 危険物取扱者乙4, 第二種電気工事士 | F11: 単独 | G11: 教育担当補助 | H11: 単独 | I11: 教育担当補助 | J11: 夜勤リーダー代行, 教育担当補助 | K11: =VLOOKUP(F11,段階マップ!$A:$B,2,FALSE()) -> 2 | L11: =VLOOKUP(G11,段階マップ!$A:$B,2,FALSE()) -> 3 | M11: =VLOOKUP(H11,段階マップ!$A:$B,2,FALSE()) -> 2 | N11: =VLOOKUP(I11,段階マップ!$A:$B,2,FALSE()) -> 3 | O11: =IF(MAX(K11:N11)>=2,1,0) -> 1
A12: 吉田 匠 | B12: E | C12: サブリーダー | D12: 61 | E12: 危険物取扱者乙4 | F12: 単独 | G12: 単独 | H12: 教育担当補助 | I12: 単独 | J12: 夜勤リーダー代行 | K12: =VLOOKUP(F12,段階マップ!$A:$B,2,FALSE()) -> 2 | L12: =VLOOKUP(G12,段階マップ!$A:$B,2,FALSE()) -> 2 | M12: =VLOOKUP(H12,段階マップ!$A:$B,2,FALSE()) -> 3 | N12: =VLOOKUP(I12,段階マップ!$A:$B,2,FALSE()) -> 2 | O12: =IF(MAX(K12:N12)>=2,1,0) -> 1
A13: 山田 悠斗 | B13: B | C13: 新人 | D13: 6 | F13: 見学 | G13: 見学 | H13: 見学 | I13: 補助 | K13: =VLOOKUP(F13,段階マップ!$A:$B,2,FALSE()) -> 0 | L13: =VLOOKUP(G13,段階マップ!$A:$B,2,FALSE()) -> 0 | M13: =VLOOKUP(H13,段階マップ!$A:$B,2,FALSE()) -> 0 | N13: =VLOOKUP(I13,段階マップ!$A:$B,2,FALSE()) -> 1 | O13: =IF(MAX(K13:N13)>=2,1,0) -> 0
A14: 佐々木 蓮 | B14: D | C14: 新人 | D14: 3 | F14: 見学 | G14: 見学 | H14: 見学 | I14: 見学 | K14: =VLOOKUP(F14,段階マップ!$A:$B,2,FALSE()) -> 0 | L14: =VLOOKUP(G14,段階マップ!$A:$B,2,FALSE()) -> 0 | M14: =VLOOKUP(H14,段階マップ!$A:$B,2,FALSE()) -> 0 | N14: =VLOOKUP(I14,段階マップ!$A:$B,2,FALSE()) -> 0 | O14: =IF(MAX(K14:N14)>=2,1,0) -> 0
A15: 松本 洋平 | B15: E | C15: 中堅 | D15: 33 | E15: 危険物取扱者乙4 | F15: 補助 | G15: 単独 | H15: 単独 | I15: 補助 | J15: 消防設備対応 | K15: =VLOOKUP(F15,段階マップ!$A:$B,2,FALSE()) -> 1 | L15: =VLOOKUP(G15,段階マップ!$A:$B,2,FALSE()) -> 2 | M15: =VLOOKUP(H15,段階マップ!$A:$B,2,FALSE()) -> 2 | N15: =VLOOKUP(I15,段階マップ!$A:$B,2,FALSE()) -> 1 | O15: =IF(MAX(K15:N15)>=2,1,0) -> 1
A16: 井上 直樹 | B16: E | C16: 一般 | D16: 14 | F16: 見学 | G16: 補助 | H16: 見学 | I16: 補助 | K16: =VLOOKUP(F16,段階マップ!$A:$B,2,FALSE()) -> 0 | L16: =VLOOKUP(G16,段階マップ!$A:$B,2,FALSE()) -> 1 | M16: =VLOOKUP(H16,段階マップ!$A:$B,2,FALSE()) -> 0 | N16: =VLOOKUP(I16,段階マップ!$A:$B,2,FALSE()) -> 1 | O16: =IF(MAX(K16:N16)>=2,1,0) -> 0

Sheet 段階マップ
A1: 段階名 | B1: 数値
A2: 見学 | B2: 0
A3: 補助 | B3: 1
A4: 単独 | B4: 2
A5: 教育担当補助 | B5: 3
A6: 教育担当 | B6: 4
